Workbook

Sheet Keterangan
A1: LEMBAR PENGODEAN DEFINISI FITUR PADA PENELITIAN TERDAHULU BERBASIS OULAD
A2: Berkas ini memuat instrumen dan hasil observasi terstruktur terhadap enam penelitian terdahulu berbasis OULAD. Setiap fitur yang dikode disebut unit. Setiap unit dikode oleh dua pengode secara terpisah pada enam dimensi, lalu ketidaksepakatan diselesaikan melalui adjudikasi. Isi berkas ini dimuat pada Lampiran A naskah skripsi, dan aturan pengisiannya dimuat pada dokumen Pedoman Pengodean.
A4: Sheet | B4: Isi
A5: Kamus_Kode | B5: Daftar kode tertutup untuk setiap dimensi beserta pertanyaan pemandu dan aturan keputusan. Kamus ini ditetapkan sebelum pengodean dimulai.
A6: Lembar_Pengodean | B6: Kode, kutipan verbatim, rujukan halaman, dan catatan untuk 16 unit. Baris 2 sampai 17 adalah pengode pertama, baris 18 sampai 33 adalah pengode kedua, keduanya pada putaran P1. Baris 34 sampai 49 adalah kode final hasil adjudikasi.
A7: Rekap_Kappa | B7: Persen kesepakatan dan kappa Cohen per dimensi yang dihitung otomatis dari baris putaran P1, beserta hasil aturan ambang ganda (nilai tengah kappa di atas 0,70 dan kappa terendah di atas 0,60).
A9: Warna sel | B9: Arti
A10: Abu-abu | B10: Kolom yang diisi peneliti utama sebelum pengodean, yaitu identitas unit, nama fitur, dan kode konsep.
A11: Kuning | B11: Kolom yang diisi pengode, yaitu kode, kutipan, rujukan halaman, status rujukan, dan catatan.
A13: Catatan | B13: Kutipan ditulis sesuai bahasa asli artikel. Tanda hubung (-) pada kolom kutipan berarti artikel tidak memuat kalimat yang dapat dikutip untuk dimensi tersebut. Urutan baris tidak boleh diubah karena rumus pada Rekap_Kappa mengandalkan posisi baris.

Sheet Kamus_Kode
A1: KAMUS KODE
A2: Cara pakai: Cari dimensi yang sedang diisi, baca pertanyaan pemandu pada baris biru, lalu pilih kode yang paling sesuai dengan kutipan. Baris hijau berisi cara memutuskan. Nomor yang dilewati, misalnya T6 dan T7, memang tidak dipakai.
A4: Dimensi | B4: Kolom pada Lembar_Pengodean | C4: Kode | D4: Arti singkat | E4: Pilih kode ini bila
A5: Konsep Fitur | B5: Kode_Konsep | C5: K1 | D5: Aktivitas di platform belajar | E5: Fitur berasal dari kegiatan mahasiswa di platform belajar daring, misalnya jumlah klik, jumlah hari aktif, atau jumlah sesi.
A6: Konsep Fitur | B6: Kode_Konsep | C6: K2 | D6: Nilai tugas atau ujian | E6: Fitur berasal dari angka nilai tugas atau ujian yang sudah diperoleh mahasiswa.
A7: Konsep Fitur | B7: Kode_Konsep | C7: K3 | D7: Status atau waktu pengumpulan | E7: Fitur berasal dari dikumpulkan atau tidaknya tugas, atau kapan tugas dikumpulkan, bukan dari angka nilainya.
A8: Aturan keputusan | C8: Kode_Konsep sudah diisi peneliti utama. Pengode tidak mengubahnya. Daftar di atas hanya untuk dibaca.
A9: Pertanyaan pemandu | C9: Apakah artikel menyebut nama tabel OULAD yang dipakai untuk membuat fitur ini?
A10: Tabel Sumber | B10: Kode_TabelSumber | C10: T1 | D10: Hanya studentVle | E10: Artikel menyebut nama tabel studentVle sebagai satu-satunya sumber fitur.
A11: Tabel Sumber | B11: Kode_TabelSumber | C11: T2 | D11: studentVle dan vle | E11: Artikel menyebut kedua nama tabel. Biasanya karena fitur memerlukan jenis aktivitas, misalnya klik pada kuis.
A12: Tabel Sumber | B12: Kode_TabelSumber | C12: T3 | D12: Hanya studentAssessment | E12: Artikel menyebut nama tabel studentAssessment sebagai satu-satunya sumber fitur.
A13: Tabel Sumber | B13: Kode_TabelSumber | C13: T4 | D13: assessments dan studentAssessment | E13: Artikel menyebut kedua nama tabel. Biasanya karena fitur memerlukan tenggat atau bobot tugas.
A14: Tabel Sumber | B14: Kode_TabelSumber | C14: T5 | D14: Gabungan tabel aktivitas dan penilaian | E14: Artikel menyebut tabel aktivitas (studentVle atau vle) dan tabel penilaian (studentAssessment atau assessments) sekaligus untuk satu fitur.
A15: Tabel Sumber | B15: Kode_TabelSumber | C15: T8 | D15: Sumber disebut tanpa nama tabel | E15: Artikel hanya memakai istilah umum, misalnya clickstream data atau data e-learning.
A16: Tabel Sumber | B16: Kode_TabelSumber | C16: T9 | D16: Sumber tidak disebut | E16: Artikel tidak menyebut sumber data fitur sama sekali. Nama tabel hanya bisa ditebak sendiri.
A17: Aturan keputusan | C17: Lihat hanya nama tabel yang tertulis di artikel. Bila harus menebak sendiri tabel mana yang dipakai, pilih T8 atau T9, lalu tulis tebakan itu di Catatan_Pengode.
A18: Pertanyaan pemandu | C18: Bisakah seorang pemrogram menulis kode penghitung fitur ini hanya dari penjelasan artikel, tanpa menentukan sendiri satu pun angka atau aturan?
A19: Formula Agregasi | B19: Kode_FormulaAgregasi | C19: F1 | D19: Dijelaskan lengkap | E19: Cara menghitung, data yang dihitung, dan cakupannya ditulis lengkap. Fitur bisa dihitung ulang tanpa menebak apa pun.
A20: Formula Agregasi | B20: Kode_FormulaAgregasi | C20: F2 | D20: Dijelaskan sebagian | E20: Cara menghitung bisa dikenali, misalnya dijumlah, tetapi ada yang tidak ditulis, seperti nilai batas, angka pembagi, atau jenis data yang dihitung.
A21: Formula Agregasi | B21: Kode_FormulaAgregasi | C21: F3 | D21: Tidak dijelaskan | E21: Artikel hanya menyebut nama fitur atau menceritakannya secara umum. Cara menghitungnya tidak bisa dikenali.
A22: Aturan keputusan | C22: Langkah 1. Apakah cara menghitungnya bisa dikenali? Bila tidak, pilih F3. Langkah 2. Bila bisa, masih adakah angka atau aturan yang harus ditentukan sendiri? Bila ada, pilih F2. Bila tidak ada, pilih F1. Rumus bernomor yang nilai di dalamnya tidak disebutkan tetap F2.
A23: Pertanyaan pemandu | C23: Data dari rentang waktu mana yang dipakai untuk menghitung fitur ini?
A24: Jendela Pengamatan | B24: Kode_JendelaPengamatan | C24: J1 | D24: Seluruh masa kuliah | E24: Dihitung dari awal sampai akhir presentasi tanpa dipotong pada waktu tertentu.
A25: Jendela Pengamatan | B25: Kode_JendelaPengamatan | C25: J2 | D25: Dipotong, persen dari panjang tiap mata kuliah | E25: Data dipotong di beberapa titik waktu. Persentasenya dihitung dari panjang masing-masing mata kuliah yang berbeda-beda.
A26: Jendela Pengamatan | B26: Kode_JendelaPengamatan | C26: J3 | D26: Dipotong, persen dari panjang yang diseragamkan | E26: Semua mata kuliah dianggap sama panjang lebih dulu, misalnya 270 hari, lalu dipotong di beberapa persentase.
A27: Jendela Pengamatan | B27: Kode_JendelaPengamatan | C27: J4 | D27: Per hari | E27: Nilai dicatat per hari, tidak digabung antarhari, dan tidak ada titik pemotongan.
A28: Jendela Pengamatan | B28: Kode_JendelaPengamatan | C28: J5 | D28: Per minggu | E28: Nilai dicatat per minggu dan tidak ada titik pemotongan.
A29: Jendela Pengamatan | B29: Kode_JendelaPengamatan | C29: J6 | D29: Dipisah sebelum dan sesudah kuliah dimulai | E29: Data dibagi menjadi masa sebelum presentasi dimulai dan masa sesudahnya.
A30: Jendela Pengamatan | B30: Kode_JendelaPengamatan | C30: J8 | D30: Tidak dijelaskan | E30: Artikel tidak menyebut rentang waktu data yang dipakai untuk menghitung fitur.
A31: Aturan keputusan | C31: Langkah 1. Apakah data dipotong di beberapa titik waktu? Bila tidak, pilih di antara J1, J4, J5, J6, atau J8. Langkah 2. Bila ya, apakah panjang semua mata kuliah diseragamkan dulu? Bila ya, pilih J3. Bila tidak, pilih J2. Bila data dipotong dan juga dihitung per hari atau per minggu, kode tetap J2 atau J3, dan satuan waktunya ditulis di Catatan_Pengode.
A32: Pertanyaan pemandu | C32: Apakah artikel menyebut bahwa skala angka fitur ini diubah, dan dengan cara apa?
A33: Normalisasi | B33: Kode_Normalisasi | C33: N1 | D33: Z-score | E33: Angka dikurangi rata-rata lalu dibagi simpangan baku. Artikel sering menyebutnya standardization atau z-score.
A34: Normalisasi | B34: Kode_Normalisasi | C34: N2 | D34: Min-max | E34: Angka diubah ke rentang tertentu, biasanya nol sampai satu. Artikel sering menyebutnya min-max scaling.
A35: Normalisasi | B35: Kode_Normalisasi | C35: N3 | D35: Cara lain | E35: Artikel memakai cara lain, misalnya transformasi logaritma. Nama caranya ditulis di Catatan_Pengode.
A36: Normalisasi | B36: Kode_Normalisasi | C36: N4 | D36: Dinyatakan tidak dinormalisasi | E36: Artikel menulis dengan jelas bahwa skala fitur tidak diubah.
A37: Normalisasi | B37: Kode_Normalisasi | C37: N8 | D37: Tidak dilaporkan | E37: Artikel tidak menyebut apa pun tentang normalisasi fitur ini.
A38: Aturan keputusan | C38: N4 dan N8 jangan tertukar. N4 hanya dipakai bila artikel menulis dengan jelas bahwa normalisasi tidak dilakukan. Artikel yang diam selalu N8. Bila artikel menyebut dari data mana rata-rata, simpangan baku, nilai minimum, atau nilai maksimum dihitung, tulis hal itu di Catatan_Pengode.
A39: Pertanyaan pemandu | C39: Apa yang dilakukan artikel terhadap data kosong pada fitur ini?
A40: Penanganan Nilai Kosong | B40: Kode_NilaiKosong | C40: V1 | D40: Dihapus | E40: Baris atau kolom yang berisi data kosong dibuang.
A41: Penanganan Nilai Kosong | B41: Kode_NilaiKosong | C41: V2 | D41: Diisi rata-rata | E41: Data kosong diganti nilai rata-rata (mean).
...

Sheet Lembar_Pengodean
A1: ID_Pengodean | B1: Putaran | C1: Pengode | D1: Penelitian | E1: Fitur_Unit | F1: Kode_Konsep | G1: Kode_TabelSumber | H1: Kutipan_TabelSumber | I1: Kode_FormulaAgregasi | J1: Kutipan_FormulaAgregasi | K1: Kode_JendelaPengamatan | L1: Kutipan_JendelaPengamatan | M1: Kode_Normalisasi | N1: Kutipan_Normalisasi | O1: Kode_NilaiKosong | P1: Kutipan_NilaiKosong | Q1: Kode_KetersediaanTemporal | R1: Kutipan_KetersediaanTemporal | S1: Rujukan_Halaman_Bagian | T1: Status_Rujukan | U1: Catatan_Pengode
A2: OULAD-Qiu2022-001 | B2: P1 | C2: Pengode 1 | D2: Qiu et al. (2022) | E2: E-learning behaviour Homepage sampai Externalquiz, Tabel 2 hlm. 8 | F2: K1 | G2: T8 | H2: the e-learning data of 6,272 learners who participated in the DDD course were used as the data source | I2: F3 | J2: bn is the n-th e-learning behaviour recorded by the e-learning platform | K2: J8 | L2: - | M2: N1 | N2: The proposed framework solves this problem by standardizing e-learning behaviour data in different dimensions with Z scores | O2: V8 | P2: There is no unified process for data cleaning ... to manage missing values, duplicate values, and abnormal values | Q2: A3 | R2: - | S2: Halaman 4, bagian (1) Data pre-processing. Halaman 7, bagian Data sources. Halaman 8, Tabel 2 dan Tabel 3. | T2: Terverifikasi | U2: Tabel Sumber. Naskah hanya menyebut data e-learning dan interaksi mahasiswa dengan VLE, tanpa nama tabel OULAD. Formula Agregasi. Naskah menyebut perilaku yang direkam platform tanpa operasi, sehingga tidak diketahui apakah nilainya jumlah klik atau frekuensi akses. Uraian number of access to resources pada halaman 1 bersifat umum dan tidak dikaitkan dengan fitur penelitian ini. Delapan perilaku terpilih juga berbeda antara Tabel 3 dan Tabel 4. Jendela Pengamatan. Rentang 2013 sampai 2014 pada bagian Data sources merujuk pengumpulan dataset, bukan jendela perhitungan fitur. Normalisasi. Rata-rata dan simpangan pada Persamaan 1 dihitung dari seluruh data perilaku ke-n pada tahap praproses, yaitu sebelum tahap pelatihan yang memuat pembagian 70:30. Naskah menyebut simbol pembagi sebagai varians, padahal rumusnya skor baku. Ketersediaan Temporal. Tidak ada titik waktu prediksi sehingga pengujian berhenti pada langkah pertama.
A3: OULAD-Qiu2022-002 | B3: P1 | C3: Pengode 1 | D3: Qiu et al. (2022) | E3: Category feature value, Persamaan 3 hlm. 4 | F3: K1 | G3: T8 | H3: the e-learning data of 6,272 learners who participated in the DDD course were used as the data source | I3: F2 | J3: Vbi is the bi characteristic value of the behaviour, λ = 0 means the student has passed the curriculum, λ = 1 means failed | K3: J8 | L3: - | M3: N1 | N3: standardizing e-learning behaviour data in different dimensions with Z scores | O3: V8 | P3: There is no unified process for data cleaning ... to manage missing values, duplicate values, and abnormal values | Q3: A3 | R3: - | S3: Halaman 4, bagian (3) Feature fusion, Persamaan 2 dan Persamaan 3. Halaman 7, bagian Data sources. Halaman 8 sampai 9, Tabel 3, Tabel 4, dan Gambar 3. | T3: Terverifikasi | U3: Tabel Sumber. Naskah hanya menyebut data e-learning, tanpa nama tabel OULAD. Formula Agregasi. Operasinya dapat dikenali sebagai kombinasi nilai maksimum dan rerata nilai karakteristik perilaku dalam satu kategori pada Persamaan 3. Nilai karakteristik pada Persamaan 2 berupa varians lintas sampel, sehingga cara memperoleh nilai per mahasiswa tidak dinyatakan. Parameter λ ditetapkan dari status lulus atau gagal mahasiswa, yang juga menjadi label prediksi. Anggota kategori tidak konsisten karena Tabel 3 memilih H, P, R, U, T, F, C, Q, sedangkan Tabel 4 dan Gambar 3 memakai H, P, G, W, T, F, E, Q. Normalisasi. Skor baku diterapkan pada data perilaku sebelum fusi, dan naskah tidak menyatakan penskalaan ulang atas nilai kategori. Ketersediaan Temporal. Tidak ada titik waktu prediksi sehingga pengujian berhenti pada langkah pertama. Ketergantungan λ pada label dicatat pada Formula Agregasi karena bukan persoalan titik waktu.
A4: OULAD-Shou2024-001 | B4: P1 | C4: Pengode 1 | D4: Shou et al. (2024) | E4: Student activity data as input daily, Algorithm 1 hlm. 9 dan hlm. 11 | F4: K1 | G4: T8 | H4: demographic data and clickstream data of student interactions in the VLE | I4: F2 | J4: the “daily” model using student activity data as input daily ... U: Student clickstream data matrix, which has a shape N × T × 20 | K4: J3 | L4: all course lengths were standardized to 270 days ... into five segments of 20%, 40%, 60%, 80%, and 100% lengths | M4: N8 | N4: - | O4: V8 | P4: samples with incorrect date fields were removed | Q4: A2 | R4: To verify the early prediction ability of the model, this paper divided the data by course time length into five segments | S4: Halaman 4, bagian 3.1 Introduction to the Dataset. Halaman 5, bagian 3.2 Data Processing. Halaman 9, Algorithm 1. Halaman 11, bagian 5.3.2 Early Risk Prediction. | T4: Terverifikasi | U4: Tabel Sumber. Naskah menyebut clickstream data tanpa nama tabel OULAD. Formula Agregasi. Algorithm 1 mendefinisikan matriks klik berukuran N × T × 20 dengan T sebagai jumlah hari kursus, sehingga nilai harian per jenis aktivitas dapat dikenali. Operasi yang menghasilkan nilai harian dari catatan klik dan makna kata summarized pada halaman 5 tidak dinyatakan. Jendela Pengamatan. Panjang seluruh presentasi diseragamkan menjadi 270 hari lebih dahulu lalu dipotong pada lima persentase, sehingga masuk J3. Satuan harian dicatat di sini sesuai aturan keputusan Jendela Pengamatan. Normalisasi. Frasa standardized to 270 days merujuk panjang kursus, bukan penskalaan fitur. Penanganan Nilai Kosong. Kalimat yang ada hanya menghapus sampel dengan tanggal tidak benar dan tidak menyebut nilai kosong, sehingga dipilih kode keterlaporan lebih rendah sesuai Aturan 8. Ketersediaan Temporal. Terdapat lima titik waktu, tetapi naskah tidak menyatakan bahwa data atau statistik acuan dibatasi sampai titik tersebut.
A5: OULAD-Shou2024-002 | B5: P1 | C5: Pengode 1 | D5: Shou et al. (2024) | E5: Weekly average click volume, hlm. 5 dan hlm. 11 | F5: K1 | G5: T8 | H5: demographic data and clickstream data of student interactions in the VLE | I5: F2 | J5: summarized the clickstream data and weekly average click volume for each segment as representative variables for the student’s virtual learning environment (VLE) interaction | K5: J3 | L5: all course lengths were standardized to 270 days ... into five segments of 20%, 40%, 60%, 80%, and 100% lengths | M5: N8 | N5: - | O5: V8 | P5: samples with incorrect date fields were removed | Q5: A2 | R5: the “weekly” model using students’ weekly activity data as input | S5: Halaman 4, bagian 3.1 Introduction to the Dataset. Halaman 5, bagian 3.2 Data Processing. Halaman 11, bagian 5.3.2 Early Risk Prediction. | T5: Terverifikasi | U5: Tabel Sumber. Naskah menyebut clickstream data tanpa nama tabel OULAD. Formula Agregasi. Operasi rerata mingguan dapat dikenali, tetapi besaran yang dirata-rata, penyebutnya, dan perlakuan bagi minggu tanpa aktivitas tidak dinyatakan. Naskah juga tidak menyatakan apakah rerata dihitung per jenis aktivitas atau atas seluruh klik. Jendela Pengamatan. Panjang seluruh presentasi diseragamkan menjadi 270 hari lebih dahulu lalu dipotong pada lima persentase, sehingga masuk J3. Satuan mingguan dicatat di sini sesuai aturan keputusan Jendela Pengamatan. Normalisasi. Frasa standardized to 270 days merujuk panjang kursus, bukan penskalaan fitur. Penanganan Nilai Kosong. Kalimat yang ada hanya menghapus sampel dengan tanggal tidak benar dan tidak menyebut nilai kosong, sehingga dipilih kode keterlaporan lebih rendah sesuai Aturan 8. Ketersediaan Temporal. Model weekly dievaluasi pada lima titik waktu yang sama, tetapi naskah tidak menyatakan bahwa data atau statistik acuan dibatasi sampai titik tersebut.
A6: OULAD-Shou2024-003 | B6: P1 | C6: Pengode 1 | D6: Shou et al. (2024) | E6: Student assessment variables matrix, Algorithm 1 hlm. 9 | F6: K2 | G6: T8 | H6: the clickstream data, assessment scores, and coded demographic data were concatenated to form the training data for the model | I6: F3 | J6: C: Student assessment variables matrix, which has shape N × T × 3 | K6: J3 | L6: all course lengths were standardized to 270 days ... into five segments of 20%, 40%, 60%, 80%, and 100% lengths | M6: N8 | N6: - | O6: V8 | P6: samples with incorrect date fields were removed | Q6: A2 | R6: Within the first 20% of the course start time, MTAPSP embodies a high prediction performance | S6: Halaman 4, bagian 3.1 Introduction to the Dataset. Halaman 5, bagian 3.2 Data Processing. Halaman 9, Algorithm 1. Halaman 12, bagian 5.3.2 Early Risk Prediction. | T6: Terverifikasi | U6: Tabel Sumber. Naskah menyebut assessment scores tanpa nama tabel OULAD. Formula Agregasi. Tiga variabel penilaian pada Algorithm 1 tidak dinamai, dan cara menempatkan skor pada sumbu hari serta pengisian hari tanpa penilaian tidak dinyatakan. Penyebutan TMA, CMA, dan Exam pada bagian 3.1 tidak dikaitkan dengan ketiga variabel tersebut. Jendela Pengamatan. Pemotongan pada lima persentase berlaku bagi the data secara keseluruhan, dan Algorithm 1 menempatkan matriks penilaian pada sumbu hari yang sama dengan matriks klik. Penanganan Nilai Kosong. Kalimat yang ada hanya menghapus sampel dengan tanggal tidak benar dan tidak menyebut nilai kosong, sehingga dipilih kode keterlaporan lebih rendah sesuai Aturan 8. Ketersediaan Temporal. Naskah mengaitkan kinerja tinggi pada titik 20% dengan fitur skor penilaian, tetapi tidak menyatakan penilaian mana yang sudah tersedia pada titik tersebut.
A7: OULAD-Masood2024-001 | B7: P1 | C7: Pengode 1 | D7: Masood et al. (2024) | E7: Number of clicks (VLE Interactions), hlm. 103692 | F7: K1 | G7: T1 | H7: The student VLE table stores click stream data (number of clicks) that indicate students’ daily activities and VLE interactions | I7: F3 | J7: VLE Interactions: This includes the number of clicks, representing the extent of student engagement with the online resources | K7: J2 | L7: at various percentages of the course length ... six phases: the start of the course, 20%, 40%, 60%, 80%, and 100% of the course studied | M7: N2 | N7: Apply min-max normalization to the entire dataset before dividing it into training and testing sets | O7: V6 | P7: all occurrences of nulls or values with noises in OULAD were eliminated or replaced with mean values | Q7: A2 | R7: Performances of at-risk students were predicted using criteria related to student demographics, VLE engagement, and assessments at various percentages of the course length | S7: Halaman 103692, bagian III.B Dataset Description. Halaman 103693 sampai 103694, bagian III.E Data Preprocessing. Halaman 103700, bagian IV Results and Discussion. | T7: Terverifikasi | U7: Tabel Sumber. Tabel student VLE disebut sebagai penyimpan number of clicks, yaitu besaran yang sama dengan atribut fitur, sehingga dikode T1. Formula Agregasi. Fitur hanya dideskripsikan sebagai atribut yang mencakup jumlah klik, tanpa operasi agregasi, satuan waktu, atau cakupan jenis aktivitas, sehingga dipilih kode keterlaporan lebih rendah sesuai Aturan 8. Jendela Pengamatan. Persentase disebut terhadap panjang kursus tanpa langkah penyeragaman durasi, sehingga dikode J2. Pernyataan enam fase hanya muncul pada bagian hasil, hasil per fase tidak dilaporkan, dan Gambar 1 yang dirujuk tidak memuat fase tersebut. Normalisasi. Nilai minimum dan maksimum dihitung dari seluruh dataset sebelum pembagian data latih dan uji, lalu parameter yang sama dipakai untuk kedua himpunan. Penanganan Nilai Kosong. Pernyataan berlaku bagi seluruh nilai kosong OULAD dengan dua perlakuan sekaligus tanpa rincian per fitur, sehingga fitur ini tercakup keduanya. Ketersediaan Temporal. Terdapat fase waktu prediksi, tetapi pembatasan data tidak dinyatakan, dan normalisasi dinyatakan memakai seluruh dataset.
A8: OULAD-Masood2024-002 | B8: P1 | C8: Pengode 1 | D8: Masood et al. (2024) | E8: Assessment Results, hlm. 103692 | F8: K2 | G8: T8 | H8: The dataset triplet, known as the student-module presentation, contains the assessment results for each student | I8: F3 | J8: Assessment Results: Continuous and final assessment scores measuring academic performance | K8: J2 | L8: at various percentages of the course length ... six phases: the start of the course, 20%, 40%, 60%, 80%, and 100% of the course studied | M8: N2 | N8: we have implemented min-max normalization across all variables | O8: V6 | P8: all occurrences of nulls or values with noises in OULAD were eliminated or replaced with mean values | Q8: A2 | R8: Performances of at-risk students were predicted using criteria related to student demographics, VLE engagement, and assessments at various percentages of the course length | S8: Halaman 103692, bagian III.B Dataset Description. Halaman 103693 sampai 103694, bagian III.E Data Preprocessing. Halaman 103700, bagian IV Results and Discussion. | T8: Terverifikasi | U8: Tabel Sumber. Naskah menyebut hasil penilaian pada triplet student-module presentation tanpa nama tabel studentAssessment. Formula Agregasi. Hanya deskripsi atribut skor, tanpa operasi seperti rerata, rerata berbobot, atau skor per penilaian. Jendela Pengamatan. Kalimat enam fase menyebut assessments secara eksplisit sebagai kriteria pada berbagai persentase panjang kursus. Normalisasi. Min-max diterapkan pada seluruh variabel dan seluruh dataset sebelum pembagian data latih dan uji, sebagaimana dinyatakan pada halaman 103694. Penanganan Nilai Kosong. Pernyataan berlaku bagi seluruh nilai kosong OULAD dengan dua perlakuan sekaligus tanpa rincian per fitur. Ketersediaan Temporal. Atribut memuat final assessment scores, sedangkan prediksi disebut dilakukan sejak fase awal kursus. Naskah tidak menyatakan bahwa skor yang belum tersedia pada fase tersebut dikeluarkan.
A9: OULAD-Althibyani2024-001 | B9: P1 | C9: Pengode 1 | D9: Althibyani (2024) | E9: Sum-click (total portal clicks), hlm. 6, dan sum-click pada Tabel 1 hlm. 8 | F9: K1 | G9: T1 | H9: the sum-click in the studentVle table | I9: F2 | J9: the total portal clicks for a particular student throughout the year and their average grade were calculated | K9: J1 | L9: the total portal clicks for a particular student throughout the year | M9: N2 | N9: The scalar normalized the features within the range of 0 to 1 | O9: V3 | P9: The imputer replaced all missing values (NA) with the median value of that specific feature | Q9: A3 | R9: - | S9: Halaman 6 sampai 7, bagian Data analysis and feature extraction. Halaman 8, bagian Model selection. Halaman 14, bagian Discussion. | T9: Terverifikasi | U9: Formula Agregasi. Operasi penjumlahan sum-click per mahasiswa dapat dikenali, tetapi kunci pengelompokan, yaitu mahasiswa saja atau mahasiswa per presentasi modul, dan batas the year tidak dinyatakan. Jendela Pengamatan. Frasa throughout the year dimaknai sebagai keseluruhan periode tanpa pemotongan, meskipun acuannya tahun dan bukan presentasi. Normalisasi. Data acuan nilai minimum dan maksimum tidak disebut. Urutan penyajian menempatkan imputer dan scaler sebelum pembagian 75/25 pada halaman 8, tetapi hal ini merupakan inferensi pengode dari urutan tulisan. Ketersediaan Temporal. Tidak ada titik waktu prediksi sehingga pengujian berhenti pada langkah pertama. Bagian pembahasan pada halaman 14 menyebut fitur keaktifan harian dan jumlah klik per hari yang tidak diuraikan pada bagian metode.
A10: OULAD-Althibyani2024-002 | B10: P1 | C10: Pengode 1 | D10: Althibyani (2024) | E10: Score (average grade), hlm. 6, dan score pada Tabel 1 hlm. 8 | F10: K2 | G10: T3 | H10: beneficial attributes were identified, including the score in the studentAssessment table | I10: F2 | J10: the sum-click and score features were grouped ... and their average grade were calculated | K10: J8 | L10: the total portal clicks for a particular student throughout the year and their average grade | M10: N2 | N10: The scalar normalized the features within the range of 0 to 1 | O10: V3 | P10: The imputer replaced all missing values (NA) with the median value of that specific feature | Q10: A3 | R10: - | S10: Halaman 6 sampai 7, bagian Data analysis and feature extraction. Halaman 8, bagian Model selection. | T10: Terverifikasi | U10: Formula Agregasi. Operasi rerata dapat dikenali, tetapi jenis penilaian yang dirata-rata, keikutsertaan ujian akhir, dan penggunaan bobot tidak dinyatakan. Jendela Pengamatan. Frasa throughout the year secara gramatikal melekat pada total klik portal, sehingga jendela rerata nilai dianggap tidak dinyatakan dan dipilih kode keterlaporan lebih rendah sesuai Aturan 8. Normalisasi. Data acuan nilai minimum dan maksimum tidak disebut. Ketersediaan Temporal. Tidak ada titik waktu prediksi sehingga pengujian berhenti pada langkah pertama.
A11: OULAD-Althibyani2024-003 | B11: P1 | C11: Pengode 1 | D11: Althibyani (2024) | E11: Summative and formative marks (weight = 0), hlm. 7, serta totalCoursework dan summativeAgainstCredits pada Tabel 1 hlm. 8 | F11: K2 | G11: T8 | H11: their summative and formative marks (weight = 0) | I11: F3 | J11: For instance, computed ... their summative and formative marks (weight = 0) | K11: J8 | L11: - | M11: N2 | N11: The scalar normalized the features within the range of 0 to 1 | O11: V3 | P11: The imputer replaced all missing values (NA) with the median value of that specific feature | Q11: A3 | R11: - | S11: Halaman 7, bagian Data analysis and feature extraction. Halaman 8, Tabel 1. | T11: Terverifikasi | U11: Tabel Sumber. Naskah menyebut marks dan bobot penilaian tanpa nama tabel OULAD. Formula Agregasi. Naskah hanya menyatakan bahwa nilai dihitung, tanpa operasi. Tabel 1 memuat nama totalCoursework dan summativeAgainstCredits tanpa definisi, dan keterangan weight = 0 tidak menjelaskan apakah hanya penilaian berbobot nol yang dihitung. Jendela Pengamatan. Rentang waktu tidak dinyatakan. Ketersediaan Temporal. Tidak ada titik waktu prediksi sehingga pengujian berhenti pada langkah pertama.
A12: OULAD-Althibyani2024-004 | B12: P1 | C12: Pengode 1 | D12: Althibyani (2024) | E12: Number of days a student submitted their coursework early, hlm. 7, dan daysEarlystdScore pada Tabel 1 hlm. 8 | F12: K3 | G12: T9 | H12: - | I12: F2 | J12: computed the number of days a student submitted their coursework early | K12: J8 | L12: - | M12: N2 | N12: The scalar normalized the features within the range of 0 to 1 | O12: V3 | P12: The imputer replaced all missing values (NA) with the median value of that specific feature | Q12: A3 | R12: - | S12: Halaman 7, bagian Data analysis and feature extraction. Halaman 8, Tabel 1. | T12: Terverifikasi | U12: Tabel Sumber. Sumber tidak disebut. Inferensi pengode mengarah pada tabel assessments untuk tenggat dan studentAssessment untuk tanggal pengumpulan. Formula Agregasi. Frasa number of days dapat dibaca sebagai selisih hari terhadap tenggat atau jumlah kejadian pengumpulan lebih awal. Aturan agregasi lintas penilaian dan perlakuan bagi pengumpulan terlambat tidak dinyatakan. Tabel 1 memuat nama daysEarlystdScore tanpa definisi, yang mengisyaratkan kombinasi dengan skor. Jendela Pengamatan. Rentang waktu tidak dinyatakan. Ketersediaan Temporal. Tidak ada titik waktu prediksi sehingga pengujian berhenti pada langkah pertama.
... A49: OULAD-Wang2025-003 | B49: Final | C49: Adjudikasi | D49: Wang (2025) | E49: First assessment, Tabel 3 hlm. 9 | F49: K2 | G49: T8 | H49: Key attributes include clickstream activity (such as the number of online resources accessed), assessment results, final grades, and withdrawal date | I49: F3 | J49: Figure 4 shows that Total Clicks and First Assessment Score are the dominant features | K49: J8 | L49: - | M49: N1 | N49: Standardization was used, transforming each feature x according to | O49: V2 | P49: For numerical features, missing entries were replaced with the feature mean | Q49: A3 | R49: - | S49: Halaman 5, bagian Open university learning analytics dataset dan Data preprocessing and feature engineering. Halaman 7, Algorithm 1. Halaman 9, Tabel 3. | T49: Terverifikasi | U49: Final. Keenam dimensi disepakati kedua pengode pada putaran P1, tanpa kandidat kode lain.

Sheet Rekap_Kappa
A1: Dimensi | B1: Persen kesepakatan | C1: Kappa Cohen | D1: Kedudukan
A2: Tabel Sumber | B2: =IF(COUNTA(Lembar_Pengodean!G2:G17)+COUNTA(Lembar_Pengodean!G18:G33)<32,"",SUMPRODUCT(--(Lembar_Pengodean!G2:G17=Lembar_Pengodean!G18:G33))/16) -> 0.9375 | C2: {=IF(COUNTA(Lembar_Pengodean!G2:G17)+COUNTA(Lembar_Pengodean!G18:G33)<32,"",IF(SUMPRODUCT(COUNTIF(Lembar_Pengodean!G2:G17,Kamus_Kode!$C$10:$C$16),COUNTIF(Lembar_Pengodean!G18:G33,Kamus_Kode!$C$10:$C$16))/256=1,"",(B2-SUMPRODUCT(COUNTIF(Lembar_Pengodean!G2:G17,Kamus_Kode!$C$10:$C$16),COUNTIF(Lembar_Pengodean!G18:G33,Kamus_Kode!$C$10:$C$16))/256)/(1-SUMPRODUCT(COUNTIF(Lembar_Pengodean!G2:G17,Kamus_Kode!$C$10:$C$16),COUNTIF(Lembar_Pengodean!G18:G33,Kamus_Kode!$C$10:$C$16))/256)))} -> 0.86324786 | D2: =IF(C2="","",IF(C2>0.6,"Masuk ambang","Di bawah ambang")) -> Masuk ambang
A3: Formula Agregasi | B3: =IF(COUNTA(Lembar_Pengodean!I2:I17)+COUNTA(Lembar_Pengodean!I18:I33)<32,"",SUMPRODUCT(--(Lembar_Pengodean!I2:I17=Lembar_Pengodean!I18:I33))/16) -> 1 | C3: =IF(COUNTA(Lembar_Pengodean!I2:I17)+COUNTA(Lembar_Pengodean!I18:I33)<32,"",IF(SUMPRODUCT(COUNTIF(Lembar_Pengodean!I2:I17,Kamus_Kode!$C$19:$C$21),COUNTIF(Lembar_Pengodean!I18:I33,Kamus_Kode!$C$19:$C$21))/256=1,"",(B3-SUMPRODUCT(COUNTIF(Lembar_Pengodean!I2:I17,Kamus_Kode!$C$19:$C$21),COUNTIF(Lembar_Pengodean!I18:I33,Kamus_Kode!$C$19:$C$21))/256)/(1-SUMPRODUCT(COUNTIF(Lembar_Pengodean!I2:I17,Kamus_Kode!$C$19:$C$21),COUNTIF(Lembar_Pengodean!I18:I33,Kamus_Kode!$C$19:$C$21))/256))) -> 1 | D3: =IF(C3="","",IF(C3>0.6,"Masuk ambang","Di bawah ambang")) -> Masuk ambang
A4: Jendela Pengamatan | B4: =IF(COUNTA(Lembar_Pengodean!K2:K17)+COUNTA(Lembar_Pengodean!K18:K33)<32,"",SUMPRODUCT(--(Lembar_Pengodean!K2:K17=Lembar_Pengodean!K18:K33))/16) -> 1 | C4: =IF(COUNTA(Lembar_Pengodean!K2:K17)+COUNTA(Lembar_Pengodean!K18:K33)<32,"",IF(SUMPRODUCT(COUNTIF(Lembar_Pengodean!K2:K17,Kamus_Kode!$C$24:$C$30),COUNTIF(Lembar_Pengodean!K18:K33,Kamus_Kode!$C$24:$C$30))/256=1,"",(B4-SUMPRODUCT(COUNTIF(Lembar_Pengodean!K2:K17,Kamus_Kode!$C$24:$C$30),COUNTIF(Lembar_Pengodean!K18:K33,Kamus_Kode!$C$24:$C$30))/256)/(1-SUMPRODUCT(COUNTIF(Lembar_Pengodean!K2:K17,Kamus_Kode!$C$24:$C$30),COUNTIF(Lembar_Pengodean!K18:K33,Kamus_Kode!$C$24:$C$30))/256))) -> 1 | D4: =IF(C4="","",IF(C4>0.6,"Masuk ambang","Di bawah ambang")) -> Masuk ambang
A5: Normalisasi | B5: =IF(COUNTA(Lembar_Pengodean!M2:M17)+COUNTA(Lembar_Pengodean!M18:M33)<32,"",SUMPRODUCT(--(Lembar_Pengodean!M2:M17=Lembar_Pengodean!M18:M33))/16) -> 1 | C5: =IF(COUNTA(Lembar_Pengodean!M2:M17)+COUNTA(Lembar_Pengodean!M18:M33)<32,"",IF(SUMPRODUCT(COUNTIF(Lembar_Pengodean!M2:M17,Kamus_Kode!$C$33:$C$37),COUNTIF(Lembar_Pengodean!M18:M33,Kamus_Kode!$C$33:$C$37))/256=1,"",(B5-SUMPRODUCT(COUNTIF(Lembar_Pengodean!M2:M17,Kamus_Kode!$C$33:$C$37),COUNTIF(Lembar_Pengodean!M18:M33,Kamus_Kode!$C$33:$C$37))/256)/(1-SUMPRODUCT(COUNTIF(Lembar_Pengodean!M2:M17,Kamus_Kode!$C$33:$C$37),COUNTIF(Lembar_Pengodean!M18:M33,Kamus_Kode!$C$33:$C$37))/256))) -> 1 | D5: =IF(C5="","",IF(C5>0.6,"Masuk ambang","Di bawah ambang")) -> Masuk ambang
A6: Penanganan Nilai Kosong | B6: =IF(COUNTA(Lembar_Pengodean!O2:O17)+COUNTA(Lembar_Pengodean!O18:O33)<32,"",SUMPRODUCT(--(Lembar_Pengodean!O2:O17=Lembar_Pengodean!O18:O33))/16) -> 1 | C6: =IF(COUNTA(Lembar_Pengodean!O2:O17)+COUNTA(Lembar_Pengodean!O18:O33)<32,"",IF(SUMPRODUCT(COUNTIF(Lembar_Pengodean!O2:O17,Kamus_Kode!$C$40:$C$46),COUNTIF(Lembar_Pengodean!O18:O33,Kamus_Kode!$C$40:$C$46))/256=1,"",(B6-SUMPRODUCT(COUNTIF(Lembar_Pengodean!O2:O17,Kamus_Kode!$C$40:$C$46),COUNTIF(Lembar_Pengodean!O18:O33,Kamus_Kode!$C$40:$C$46))/256)/(1-SUMPRODUCT(COUNTIF(Lembar_Pengodean!O2:O17,Kamus_Kode!$C$40:$C$46),COUNTIF(Lembar_Pengodean!O18:O33,Kamus_Kode!$C$40:$C$46))/256))) -> 1 | D6: =IF(C6="","",IF(C6>0.6,"Masuk ambang","Di bawah ambang")) -> Masuk ambang
A7: Ketersediaan Temporal | B7: =IF(COUNTA(Lembar_Pengodean!Q2:Q17)+COUNTA(Lembar_Pengodean!Q18:Q33)<32,"",SUMPRODUCT(--(Lembar_Pengodean!Q2:Q17=Lembar_Pengodean!Q18:Q33))/16) -> 1 | C7: =IF(COUNTA(Lembar_Pengodean!Q2:Q17)+COUNTA(Lembar_Pengodean!Q18:Q33)<32,"",IF(SUMPRODUCT(COUNTIF(Lembar_Pengodean!Q2:Q17,Kamus_Kode!$C$49:$C$51),COUNTIF(Lembar_Pengodean!Q18:Q33,Kamus_Kode!$C$49:$C$51))/256=1,"",(B7-SUMPRODUCT(COUNTIF(Lembar_Pengodean!Q2:Q17,Kamus_Kode!$C$49:$C$51),COUNTIF(Lembar_Pengodean!Q18:Q33,Kamus_Kode!$C$49:$C$51))/256)/(1-SUMPRODUCT(COUNTIF(Lembar_Pengodean!Q2:Q17,Kamus_Kode!$C$49:$C$51),COUNTIF(Lembar_Pengodean!Q18:Q33,Kamus_Kode!$C$49:$C$51))/256))) -> 1 | D7: =IF(C7="","",IF(C7>0.6,"Masuk ambang","Di bawah ambang")) -> Masuk ambang
A9: Nilai tengah kappa enam dimensi | C9: =IF(COUNT(C2:C7)<6,"",MEDIAN(C2:C7)) -> 1 | D9: harus > 0,70
A10: Kappa terendah enam dimensi | C10: =IF(COUNT(C2:C7)<6,"",MIN(C2:C7)) -> 0.86324786 | D10: harus > 0,60
A11: Hasil aturan ambang ganda | C11: =IF(OR(C9="",C10=""),"",IF(AND(C9>0.7,C10>0.6),"LOLOS","TIDAK LOLOS")) -> LOLOS
A13: Nilai di lembar ini dihitung dari baris Putaran P1 saja, yaitu 16 unit per pengode, dan merupakan angka yang dilaporkan pada naskah skripsi.
A14: Konsep Fitur tidak dihitung karena Kode_Konsep diisi peneliti utama sebagai bagian dari definisi unit.
A15: Jangan menyisipkan, menghapus, atau mengurutkan ulang baris pada Lembar_Pengodean. Rumus mengasumsikan urutan unit pada blok Pengode 1 (baris 2 sampai 17) dan Pengode 2 (baris 18 sampai 33) identik.
A16: Adjudikasi dilakukan dengan menambah baris baru di bawah pada Lembar_Pengodean, isi Putaran dengan Final. Baris tersebut tidak ikut terhitung di sini.
